<?xml version="1.0"?>
<robot name="robot_arm">
  <!-- Base link -->
  <link name="base_link">
    <visual>
      <geometry>
        <cylinder length="0.1" radius="0.05"/>
      </geometry>
      <material name="gray">
        <color rgba="0.5 0.5 0.5 1.0"/>
      </material>
    </visual>
    <collision>
      <geometry>
        <cylinder length="0.1" radius="0.05"/>
      </geometry>
    </collision>
    <inertial>
      <mass value="2.0"/>
      <origin xyz="0 0 0" rpy="0 0 0"/>
      <inertia ixx="0.0052" ixy="0" ixz="0" iyy="0.0052" iyz="0" izz="0.005"/>
    </inertial>
  </link>

  <!-- First arm segment -->
  <link name="arm1">
    <visual>
      <geometry>
        <box size="0.03 0.03 0.3"/>
      </geometry>
      <material name="orange">
        <color rgba="1.0 0.6 0.0 1.0"/>
      </material>
    </visual>
    <collision>
      <geometry>
        <box size="0.03 0.03 0.3"/>
      </geometry>
    </collision>
    <inertial>
      <mass value="1.0"/>
      <origin xyz="0 0 0.15" rpy="0 0 0"/>
      <inertia ixx="0.0075" ixy="0" ixz="0" iyy="0.0075" iyz="0" izz="0.00015"/>
    </inertial>
  </link>

  <!-- Joint 1 -->
  <joint name="base_to_arm1" type="revolute">
    <parent link="base_link"/>
    <child link="arm1"/>
    <origin xyz="0 0 0.05" rpy="0 0 0"/>
    <axis xyz="0 0 1"/>
    <limit lower="-3.14159" upper="3.14159" effort="100" velocity="1"/>
  </joint>

  <!-- End effector -->
  <link name="gripper">
    <visual>
      <geometry>
        <box size="0.02 0.02 0.05"/>
      </geometry>
      <material name="red">
        <color rgba="0.8 0.2 0.2 1.0"/>
      </material>
    </visual>
    <collision>
      <geometry>
        <box size="0.02 0.02 0.05"/>
      </geometry>
    </collision>
    <inertial>
      <mass value="0.2"/>
      <origin xyz="0 0 0" rpy="0 0 0"/>
      <inertia ixx="0.0001" ixy="0" ixz="0" iyy="0.0001" iyz="0" izz="0.0001"/>
    </inertial>
  </link>

  <!-- Joint 2 -->
  <joint name="arm1_to_gripper" type="prismatic">
    <parent link="arm1"/>
    <child link="gripper"/>
    <origin xyz="0 0 0.3" rpy="0 0 0"/>
    <axis xyz="0 0 1"/>
    <limit lower="0" upper="0.1" effort="50" velocity="0.5"/>
  </joint>
</robot>